Workbook
Name Category: OFFSET('Sales Analysis'!$AF$1,1,0,COUNT('Sales Analysis'!$AG:$AG))
Name CategoryRange: OFFSET('Sales Analysis'!$AF$1,1,1,COUNT('Sales Analysis'!$AG:$AG))
Name Slicer_Client_Type: #N/A
Name Slicer_Month: #N/A
Name Slicer_Payment: #N/A
Name Slicer_Year: #N/A

Sheet RAW DATA_MotorPH_Products_List_
A1: EntrNo | B1: EntrName | C1: EntrDetails | D1: Manufacturing Date | E1: Acquisiton | F1: UnitPrice
A2: 1 | B2: Honda CBR500R | C2: Sport / Parallel-twin, liquid-cooled, 471cc, 6-speed | D2: 2021 | E2: 2023 | F2: 389000
A3: 2 | B3: Yamaha MT-15 | C3: Naked bike / Single cylinder, liquid-cooled, 155cc, 6-speed | D3: 2022 | E3: 2023 | F3: 178000
A4: 3 | B4: Kawasaki Ninja 400 | C4: Sport / Parallel-twin, liquid-cooled, 399cc, 6-speed | D4: 2023 | E4: 2024 | F4: 340000
A5: 4 | B5: Suzuki Raider R150 Fi | C5: Underbone / Single cylinder, liquid-cooled, 150cc, 6-speed | D5: 2020 | E5: 2021 | F5: 119900
A6: 5 | B6: Royal Enfield Classic 350 | C6: Classic / Single cylinder, air-cooled, 349cc, 5-speed | D6: 2022 | E6: 2023 | F6: 250000
A7: 6 | B7: CFMoto 300NK | C7: Naked bike / Single cylinder, liquid-cooled, 292cc, 6-speed | D7: 2021 | E7: 2022 | F7: 165000
A8: 7 | B8: Bristol Veloce 500 | C8: Cafe racer / Twin cylinder, air-cooled, 471cc, 6-speed | D8: 2022 | E8: 2023 | F8: 328000
A9: 8 | B9: KTM Duke 200 | C9: Naked bike / Single cylinder, liquid-cooled, 199cc, 6-speed | D9: 2023 | E9: 2024 | F9: 178000
A10: 9 | B10: Yamaha XSR155 | C10: Retro / Single cylinder, liquid-cooled, 155cc, 6-speed | D10: 2022 | E10: 2023 | F10: 182000
A11: 10 | B11: Bajaj Dominar 400 | C11: Sport touring / Single cylinder, liquid-cooled, 373cc, 6-speed | D11: 2021 | E11: 2022 | F11: 199900
A12: 11 | B12: Yamaha NMAX 155 | C12: Scooter / Single cylinder, liquid-cooled, 155cc, CVT | D12: 2022 | E12: 2023 | F12: 151900
A13: 12 | B13: Honda ADV 160 | C13: Scooter / Single cylinder, liquid-cooled, 157cc, CVT | D13: 2023 | E13: 2024 | F13: 164900
... A51: 50 | B51: SYM Husky 150 | C51: Underbone / Single cylinder, air-cooled, 150cc, CVT | D51: 2022 | E51: 2023 | F51: 72900

Sheet Dashboard

Sheet Sales Analysis
A1: Row Labels | B1: Sum of Total | D1: Sum of Mark up Rate | E1: Sum of Total | G1: Row Labels | H1: Sum of Mark up Rate | I1: Sum of Total | L1: TRUE | M1: TRUE | N1: TRUE | P1: Product | Q1: Displacement (cc) | R1: Sum of Total | S1: Sum of Quantity | V1: =VLOOKUP(1,U:Y,2,0) -> Moto Guzzi V7 Stone | W1: =VLOOKUP(1,U:Y,3,0) -> 853cc | X1: =VLOOKUP(1,U:Y,4,0) -> 317629000 | Y1: =VLOOKUP(1,U:Y,5,0) -> 461 | AA1: 1 | AB1: =COUNT(S:S)-9 -> 41 | AC1: =MIN(AA1:AB1) -> 1 | AF1: Row Labels | AG1: Sum of Total | AJ1: =VLOOKUP(1,$AI:$AK,2,0) -> Scooter | AK1: =VLOOKUP(1,$AI:$AK,3,0) -> 753773100 | AM1: Row Labels | AN1: Sum of Total | AP1: Row Labels | AQ1: Sum of Total
A2: 1 | B2: 173417000 | D2: 3.4062387e+09 | E2: 4445561800 | G2: January | H2: 9029384.6 | I2: 11738200 | K2: Month | L2: Sales | M2: Profit | N2: Profit % | P2: Aprilia SR GT 200 | Q2: 174cc | R2: 67233000 | S2: 307 | AF2: Adventure | AG2: 390820700 | AM2: Retail | AN2: 2399268400 | AP2: Cash | AQ2: 1412997900
A3: 2 | B3: 152285900 | G3: June | H3: 1.1547887e+09 | I3: 1515957700 | K3: January | L3: =IF($L$1=TRUE,SUMIFS(I:I,G:G,K3),NA()) -> 11738200 | M3: =IF($M$1=TRUE,SUMIFS(I:I,G:G,K3)-SUMIFS(H:H,G:G,K3),NA()) -> 2708815.4 | N3: =IF($N$1=TRUE,M3/SUMIFS(H:H,G:G,K3),"") -> 0.3 | P3: Bajaj CT125 | Q3: 125cc | R3: 34561100 | S3: 509 | U3: =RANK(X3,$X$3:$X$52) -> 30 | V3: {=OFFSET($P$1,1,0,COUNT($R:$R))} -> Aprilia SR GT 200 | W3: {=OFFSET($P$1,1,1,COUNT($R:$R))} -> 174cc | X3: {=OFFSET($P$1,1,2,COUNT($R:$R))} -> 67233000 | Y3: {=OFFSET($P$1,1,3,COUNT($R:$R))} -> 307 | AA3: {=OFFSET($P$1,$AC$1,0,10)} -> Aprilia SR GT 200 | AB3: {=OFFSET($P$1,$AC$1,2,10)} -> 67233000 | AF3: Cafe racer | AG3: 171473000 | AI3: =RANK(AK3,$AK$3:$AK$19) -> 5 | AJ3: {=OFFSET($AF$1,1,0,COUNT($AG:$AG))} -> Adventure | AK3: {=OFFSET($AF$1,1,1,COUNT($AG:$AG))} -> 390820700 | AM3: Wholesale | AN3: 2046293400 | AP3: Credit card | AQ3: 1570042600
A4: 3 | B4: 195578000 | G4: July | H4: 1.1468541e+09 | I4: 1493211800 | K4: June | L4: =IF($L$1=TRUE,SUMIFS(I:I,G:G,K4),NA()) -> 1515957700 | M4: =IF($M$1=TRUE,SUMIFS(I:I,G:G,K4)-SUMIFS(H:H,G:G,K4),NA()) -> 3.6116904e+08 | N4: =IF($N$1=TRUE,M4/SUMIFS(H:H,G:G,K4),"") -> 0.3127577 | P4: Bajaj Dominar 400 | Q4: 373cc | R4: 83558200 | S4: 418 | U4: =RANK(X4,$X$3:$X$52) -> 40 | V4: Bajaj CT125 | W4: 125cc | X4: 34561100 | Y4: 509 | AA4: Bajaj CT125 | AB4: 34561100 | AF4: Classic | AG4: 114500000 | AI4: =RANK(AK4,$AK$3:$AK$19) -> 8 | AJ4: Cafe racer | AK4: 171473000 | AP4: Transfer | AQ4: 1462521300
A5: 4 | B5: 105095800 | D5: Total Sales | E5: =GETPIVOTDATA("Sum of Total",$D$1) -> 4445561800 | G5: August | H5: 1.0955665e+09 | I5: 1424654100 | K5: July | L5: =IF($L$1=TRUE,SUMIFS(I:I,G:G,K5),NA()) -> 1493211800 | M5: =IF($M$1=TRUE,SUMIFS(I:I,G:G,K5)-SUMIFS(H:H,G:G,K5),NA()) -> 3.4635767e+08 | N5: =IF($N$1=TRUE,M5/SUMIFS(H:H,G:G,K5),"") -> 0.30200673 | P5: Benelli 502C | Q5: 500cc | R5: 134016000 | S5: 384 | U5: =RANK(X5,$X$3:$X$52) -> 21 | V5: Bajaj Dominar 400 | W5: 373cc | X5: 83558200 | Y5: 418 | AA5: Bajaj Dominar 400 | AB5: 83558200 | AF5: Commuter | AG5: 53425100 | AI5: =RANK(AK5,$AK$3:$AK$19) -> 10 | AJ5: Classic | AK5: 114500000
A6: 5 | B6: 171255800 | D6: Total Profit | E6: =GETPIVOTDATA("Sum of Total",$D$1)-GETPIVOTDATA("Sum of Mark up Rate",$D$1) -> 1.0393231e+09 | K6: August | L6: =IF($L$1=TRUE,SUMIFS(I:I,G:G,K6),NA()) -> 1424654100 | M6: =IF($M$1=TRUE,SUMIFS(I:I,G:G,K6)-SUMIFS(H:H,G:G,K6),NA()) -> 3.2908755e+08 | N6: =IF($N$1=TRUE,M6/SUMIFS(H:H,G:G,K6),"") -> 0.30038116 | P6: BMW G 310 GS | Q6: 313cc | R6: 136320000 | S6: 426 | U6: =RANK(X6,$X$3:$X$52) -> 11 | V6: Benelli 502C | W6: 500cc | X6: 134016000 | Y6: 384 | AA6: Benelli 502C | AB6: 134016000 | AF6: Cruiser | AG6: 635461000 | AI6: =RANK(AK6,$AK$3:$AK$19) -> 15 | AJ6: Commuter | AK6: 53425100
A7: 6 | B7: 110759200 | D7: Profit Percentage | E7: =E6/GETPIVOTDATA("Sum of Mark up Rate",$D$1) -> 0.30512338 | P7: BMW R nineT | Q7: 0 | R7: 225865000 | S7: 227 | U7: =RANK(X7,$X$3:$X$52) -> 10 | V7: BMW G 310 GS | W7: 313cc | X7: 136320000 | Y7: 426 | AA7: BMW G 310 GS | AB7: 136320000 | AF7: Dual-sport | AG7: 306517800 | AI7: =RANK(AK7,$AK$3:$AK$19) -> 2 | AJ7: Cruiser | AK7: 635461000
A8: 7 | B8: 129450900 | P8: Bristol Bobber 650 | Q8: 649cc | R8: 228850000 | S8: 575 | U8: =RANK(X8,$X$3:$X$52) -> 3 | V8: BMW R nineT | W8: 0 | X8: 225865000 | Y8: 227 | AA8: BMW R nineT | AB8: 225865000 | AF8: Heritage | AG8: 543494000 | AI8: =RANK(AK8,$AK$3:$AK$19) -> 7 | AJ8: Dual-sport | AK8: 306517800
A9: 8 | B9: 144301800 | P9: Bristol Veloce 500 | Q9: 471cc | R9: 75440000 | S9: 230 | U9: =RANK(X9,$X$3:$X$52) -> 2 | V9: Bristol Bobber 650 | W9: 649cc | X9: 228850000 | Y9: 575 | AA9: Bristol Bobber 650 | AB9: 228850000 | AF9: Naked bike | AG9: 552254000 | AI9: =RANK(AK9,$AK$3:$AK$19) -> 4 | AJ9: Heritage | AK9: 543494000
A10: 9 | B10: 121906400 | P10: CFMoto 300NK | Q10: 292cc | R10: 70620000 | S10: 428 | U10: =RANK(X10,$X$3:$X$52) -> 24 | V10: Bristol Veloce 500 | W10: 471cc | X10: 75440000 | Y10: 230 | AA10: Bristol Veloce 500 | AB10: 75440000 | AF10: Retro | AG10: 63700000 | AI10: =RANK(AK10,$AK$3:$AK$19) -> 3 | AJ10: Naked bike | AK10: 552254000
A11: 10 | B11: 128942300 | P11: CFMoto 300SR | Q11: 292cc | R11: 81840000 | S11: 496 | U11: =RANK(X11,$X$3:$X$52) -> 29 | V11: CFMoto 300NK | W11: 292cc | X11: 70620000 | Y11: 428 | AA11: CFMoto 300NK | AB11: 70620000 | AF11: Scooter | AG11: 753773100 | AI11: =RANK(AK11,$AK$3:$AK$19) -> 14 | AJ11: Retro | AK11: 63700000
A12: 11 | B12: 100593700 | P12: CFMoto 650MT | Q12: 649cc | R12: 147315000 | S12: 427 | U12: =RANK(X12,$X$3:$X$52) -> 23 | V12: CFMoto 300SR | W12: 292cc | X12: 81840000 | Y12: 496 | AA12: CFMoto 300SR | AB12: 81840000 | AF12: Scrambler | AG12: 89680000 | AI12: =RANK(AK12,$AK$3:$AK$19) -> 1 | AJ12: Scooter | AK12: 753773100
A13: 12 | B13: 158048600 | P13: Harley-Davidson Street 750 | Q13: 749cc | R13: 102295000 | S13: 205 | U13: =RANK(X13,$X$3:$X$52) -> 7 | V13: CFMoto 650MT | W13: 649cc | X13: 147315000 | Y13: 427 | AF13: Sport | AG13: 372471000 | AI13: =RANK(AK13,$AK$3:$AK$19) -> 12 | AJ13: Scrambler | AK13: 89680000
A14: 13 | B14: 115194100 | P14: Honda ADV 160 | Q14: 157cc | R14: 73875200 | S14: 448 | U14: =RANK(X14,$X$3:$X$52) -> 17 | V14: Harley-Davidson Street 750 | W14: 749cc | X14: 102295000 | Y14: 205 | AF14: Sport touring | AG14: 83558200 | AI14: =RANK(AK14,$AK$3:$AK$19) -> 6 | AJ14: Sport | AK14: 372471000
A15: 14 | B15: 199164800 | P15: Honda CBR500R | Q15: 471cc | R15: 143541000 | S15: 369 | U15: =RANK(X15,$X$3:$X$52) -> 26 | V15: Honda ADV 160 | W15: 157cc | X15: 73875200 | Y15: 448 | AF15: Standard | AG15: 27215500 | AI15: =RANK(AK15,$AK$3:$AK$19) -> 13 | AJ15: Sport touring | AK15: 83558200
A16: 15 | B16: 153205700 | P16: Honda Click 125i | Q16: 125cc | R16: 23703700 | S16: 293 | U16: =RANK(X16,$X$3:$X$52) -> 9 | V16: Honda CBR500R | W16: 471cc | X16: 143541000 | Y16: 369 | AF16: Street | AG16: 48151800 | AI16: =RANK(AK16,$AK$3:$AK$19) -> 17 | AJ16: Standard | AK16: 27215500
A17: 16 | B17: 75438800 | P17: Honda CRF300L | Q17: 286cc | R17: 83190800 | S17: 292 | U17: =RANK(X17,$X$3:$X$52) -> 47 | V17: Honda Click 125i | W17: 125cc | X17: 23703700 | Y17: 293 | AF17: Touring | AG17: 147315000 | AI17: =RANK(AK17,$AK$3:$AK$19) -> 16 | AJ17: Street | AK17: 48151800
A18: 17 | B18: 182334200 | P18: Honda Rebel 1100 | Q18: 1084cc | R18: 170300000 | S18: 262 | U18: =RANK(X18,$X$3:$X$52) -> 22 | V18: Honda CRF300L | W18: 286cc | X18: 83190800 | Y18: 292 | AF18: Underbone | AG18: 91751600 | AI18: =RANK(AK18,$AK$3:$AK$19) -> 9 | AJ18: Touring | AK18: 147315000
A19: 18 | B19: 141175700 | P19: Husqvarna Svartpilen 401 | Q19: 373cc | R19: 89680000 | S19: 304 | U19: =RANK(X19,$X$3:$X$52) -> 5 | V19: Honda Rebel 1100 | W19: 1084cc | X19: 170300000 | Y19: 262 | AI19: =RANK(AK19,$AK$3:$AK$19) -> 11 | AJ19: Underbone | AK19: 91751600
A20: 19 | B20: 89101900 | P20: Italjet Dragster 200 | Q20: 181cc | R20: 112999000 | S20: 391 | U20: =RANK(X20,$X$3:$X$52) -> 19 | V20: Husqvarna Svartpilen 401 | W20: 373cc | X20: 89680000 | Y20: 304
A21: 20 | B21: 71876800 | P21: Kawasaki KLX 230 | Q21: 233cc | R21: 75023000 | S21: 377 | U21: =RANK(X21,$X$3:$X$52) -> 15 | V21: Italjet Dragster 200 | W21: 181cc | X21: 112999000 | Y21: 391
A22: 21 | B22: 147760500 | P22: Kawasaki Ninja 400 | Q22: 399cc | R22: 86700000 | S22: 255 | U22: =RANK(X22,$X$3:$X$52) -> 25 | V22: Kawasaki KLX 230 | W22: 233cc | X22: 75023000 | Y22: 377
A23: 22 | B23: 170132200 | P23: Kawasaki Z400 | Q23: 399cc | R23: 129421000 | S23: 391 | U23: =RANK(X23,$X$3:$X$52) -> 20 | V23: Kawasaki Ninja 400 | W23: 399cc | X23: 86700000 | Y23: 255
A24: 23 | B24: 138171000 | P24: Keeway RKS 150 Sport | Q24: 149cc | R24: 27215500 | S24: 395 | U24: =RANK(X24,$X$3:$X$52) -> 12 | V24: Kawasaki Z400 | W24: 399cc | X24: 129421000 | Y24: 391
A25: 24 | B25: 149633300 | P25: KTM 790 Duke | Q25: 799cc | R25: 209051000 | S25: 349 | U25: =RANK(X25,$X$3:$X$52) -> 46 | V25: Keeway RKS 150 Sport | W25: 149cc | X25: 27215500 | Y25: 395
A26: 25 | B26: 184962300 | P26: KTM Duke 200 | Q26: 199cc | R26: 21716000 | S26: 122 | U26: =RANK(X26,$X$3:$X$52) -> 4 | V26: KTM 790 Duke | W26: 799cc | X26: 209051000 | Y26: 349
A27: 26 | B27: 177020800 | P27: KTM RC 200 | Q27: 199cc | R27: 60390000 | S27: 305 | U27: =RANK(X27,$X$3:$X$52) -> 48 | V27: KTM Duke 200 | W27: 199cc | X27: 21716000 | Y27: 122
A28: 27 | B28: 154963200 | P28: Moto Guzzi V7 Stone | Q28: 853cc | R28: 317629000 | S28: 461 | U28: =RANK(X28,$X$3:$X$52) -> 32 | V28: KTM RC 200 | W28: 199cc | X28: 60390000 | Y28: 305
A29: 28 | B29: 152515700 | P29: Moto Morini X-Cape 650 | Q29: 649cc | R29: 109593000 | S29: 297 | U29: =RANK(X29,$X$3:$X$52) -> 1 | V29: Moto Guzzi V7 Stone | W29: 853cc | X29: 317629000 | Y29: 461
A30: 29 | B30: 145642200 | P30: Motorstar Xplorer 250R | Q30: 223cc | R30: 27851700 | S30: 353 | U30: =RANK(X30,$X$3:$X$52) -> 16 | V30: Moto Morini X-Cape 650 | W30: 649cc | X30: 109593000 | Y30: 297
A31: 30 | B31: 158382600 | P31: Royal Enfield Classic 350 | Q31: 349cc | R31: 114500000 | S31: 458 | U31: =RANK(X31,$X$3:$X$52) -> 45 | V31: Motorstar Xplorer 250R | W31: 223cc | X31: 27851700 | Y31: 353
A32: 31 | B32: 147250600 | P32: Rusi Flash 125 | Q32: 125cc | R32: 18864000 | S32: 393 | U32: =RANK(X32,$X$3:$X$52) -> 14 | V32: Royal Enfield Classic 350 | W32: 349cc | X32: 114500000 | Y32: 458
P33: Suzuki Avenis 125 | Q33: 124cc | R33: 33717800 | S33: 422 | U33: =RANK(X33,$X$3:$X$52) -> 49 | V33: Rusi Flash 125 | W33: 125cc | X33: 18864000 | Y33: 393
P34: Suzuki Burgman Street 125 | Q34: 124cc | R34: 33654400 | S34: 416 | U34: =RANK(X34,$X$3:$X$52) -> 41 | V34: Suzuki Avenis 125 | W34: 124cc | X34: 33717800 | Y34: 422
P35: Suzuki GSX-S150 | Q35: 147cc | R35: 37125000 | S35: 297 | U35: =RANK(X35,$X$3:$X$52) -> 42 | V35: Suzuki Burgman Street 125 | W35: 124cc | X35: 33654400 | Y35: 416
P36: Suzuki Raider R150 Fi | Q36: 150cc | R36: 38368000 | S36: 320 | U36: =RANK(X36,$X$3:$X$52) -> 39 | V36: Suzuki GSX-S150 | W36: 147cc | X36: 37125000 | Y36: 297
P37: SYM Husky 150 | Q37: 150cc | R37: 13851000 | S37: 190 | U37: =RANK(X37,$X$3:$X$52) -> 38 | V37: Suzuki Raider R150 Fi | W37: 150cc | X37: 38368000 | Y37: 320
P38: SYM Jet X 150 | Q38: 149cc | R38: 33408000 | S38: 261 | U38: =RANK(X38,$X$3:$X$52) -> 50 | V38: SYM Husky 150 | W38: 150cc | X38: 13851000 | Y38: 190
P39: TVS Apache RTR 200 4V | Q39: 197cc | R39: 28251000 | S39: 219 | U39: =RANK(X39,$X$3:$X$52) -> 43 | V39: SYM Jet X 150 | W39: 149cc | X39: 33408000 | Y39: 261
P40: Vespa GTS Super 300 | Q40: 278cc | R40: 144474000 | S40: 363 | U40: =RANK(X40,$X$3:$X$52) -> 44 | V40: TVS Apache RTR 200 4V | W40: 197cc | X40: 28251000 | Y40: 219
...

Sheet Product Analysis
A1: Unit Price (PHP) | D1: Product Type | E1: Count | F1: Count %
D2: Scooter | E2: 12 | F2: 0.24
A3: Mean | B3: 257872 | D3: Naked bike | E3: 7 | F3: 0.14 | H3: Year | I3: Manufactured | L3: Year | M3: Product Count | N3: Total Unit Price (PHP) | O3: Average Unit Price (PHP) | Q3: Product Type | R3: Product Name | S3: Total Unit Price (PHP) | U3: Engine Type | V3: Count | W3: Count % | Y3: Product Type | Z3: Count | AA3: Count %
A4: Standard Error | B4: 25940.221 | D4: Sport | E4: 4 | F4: 0.08 | H4: 2020 | I4: 5 | L4: Scooter | M4: 12 | N4: 2245500 | O4: 187125 | Q4: Scooter | R4: Vespa GTS Super 300 | S4: 398000 | U4: Parallel-twin | V4: =COUNTIFS(CLEANED_MotorPH_Products_List_2!E:E,'Product Analysis'!U4) -> 9 | W4: =V4/SUM($V$4:$V$8) -> 0.18 | Y4: Scooter | Z4: =COUNTIFS(CLEANED_MotorPH_Products_List_2!C:C,'Product Analysis'!Y4) -> 12 | AA4: =Z4/SUM($Z$4:$Z$20) -> 0.24
A5: Median | B5: 204950 | D5: Adventure | E5: 4 | F5: 0.08 | H5: 2021 | I5: 8 | L5: Cruiser | M5: 4 | N5: 1896000 | O5: 474000 | R5: Yamaha XMAX 300 | S5: 319000 | U5: Single cylinder | V5: =COUNTIFS(CLEANED_MotorPH_Products_List_2!E:E,'Product Analysis'!U5) -> 37 | W5: =V5/SUM($V$4:$V$8) -> 0.74 | Y5: Cruiser | Z5: =COUNTIFS(CLEANED_MotorPH_Products_List_2!C:C,'Product Analysis'!Y5) -> 4 | AA5: =Z5/SUM($Z$4:$Z$20) -> 0.08
A6: Mode | B6: 178000 | D6: Cruiser | E6: 4 | F6: 0.08 | H6: 2022 | I6: 16 | L6: Naked bike | M6: 7 | N6: 1705000 | O6: 243571.43 | R6: Italjet Dragster 200 | S6: 289000 | U6: Twin cylinder | V6: =COUNTIFS(CLEANED_MotorPH_Products_List_2!E:E,'Product Analysis'!U6) -> 1 | W6: =V6/SUM($V$4:$V$8) -> 0.02 | Y6: Naked bike | Z6: =COUNTIFS(CLEANED_MotorPH_Products_List_2!C:C,'Product Analysis'!Y6) -> 7 | AA6: =Z6/SUM($Z$4:$Z$20) -> 0.14
A7: Standard Deviation | B7: 183425.06 | D7: Underbone | E7: 3 | F7: 0.06 | H7: 2023 | I7: 21 | L7: Heritage | M7: 2 | N7: 1684000 | O7: 842000 | R7: Aprilia SR GT 200 | S7: 219000 | U7: V-twin | V7: =COUNTIFS(CLEANED_MotorPH_Products_List_2!E:E,'Product Analysis'!U7) -> 2 | W7: =V7/SUM($V$4:$V$8) -> 0.04 | Y7: Heritage | Z7: =COUNTIFS(CLEANED_MotorPH_Products_List_2!C:C,'Product Analysis'!Y7) -> 2 | AA7: =Z7/SUM($Z$4:$Z$20) -> 0.04
A8: Sample Variance | B8: 3.3644753e+10 | D8: Dual-sport | E8: 3 | F8: 0.06 | H8: Grand Total | I8: 50 | L8: Sport | M8: 4 | N8: 1092000 | O8: 273000 | R8: Vespa Primavera 150 | S8: 210000 | U8: Flat twin | V8: =COUNTIFS(CLEANED_MotorPH_Products_List_2!E:E,'Product Analysis'!U8) -> 1 | W8: =V8/SUM($V$4:$V$8) -> 0.02 | Y8: Sport | Z8: =COUNTIFS(CLEANED_MotorPH_Products_List_2!C:C,'Product Analysis'!Y8) -> 4 | AA8: =Z8/SUM($Z$4:$Z$20) -> 0.08
A9: Kurtosis | B9: 4.642671 | D9: Cafe racer | E9: 2 | F9: 0.04 | L9: Adventure | M9: 4 | N9: 1015900 | O9: 253975 | R9: Honda ADV 160 | S9: 164900 | Y9: Adventure | Z9: =COUNTIFS(CLEANED_MotorPH_Products_List_2!C:C,'Product Analysis'!Y9) -> 4 | AA9: =Z9/SUM($Z$4:$Z$20) -> 0.08
A10: Skewness | B10: 1.8317017 | D10: Commuter | E10: 2 | F10: 0.04 | H10: Year | I10: Acquisition | J10: Acquisition % | L10: Dual-sport | M10: 3 | N10: 782900 | O10: 260966.67 | R10: Yamaha NMAX 155 | S10: 151900 | U10: Cooling System | V10: Count | W10: Count % | Y10: Dual-sport | Z10: =COUNTIFS(CLEANED_MotorPH_Products_List_2!C:C,'Product Analysis'!Y10) -> 3 | AA10: =Z10/SUM($Z$4:$Z$20) -> 0.06
A11: Range | B11: 947000 | D11: Heritage | E11: 2 | F11: 0.04 | H11: 2021 | I11: 5 | J11: =I11/$I$15 -> 0.1 | L11: Cafe racer | M11: 2 | N11: 597000 | O11: 298500 | R11: SYM Jet X 150 | S11: 128000 | U11: liquid-cooled | V11: =COUNTIFS(CLEANED_MotorPH_Products_List_2!F:F,'Product Analysis'!U11) -> 34 | W11: =V11/SUM($V$11:$V$14) -> 0.68 | Y11: Cafe racer | Z11: =COUNTIFS(CLEANED_MotorPH_Products_List_2!C:C,'Product Analysis'!Y11) -> 2 | AA11: =Z11/SUM($Z$4:$Z$20) -> 0.04
A12: Minimum | B12: 48000 | D12: Classic | E12: 1 | F12: 0.02 | H12: 2022 | I12: 7 | J12: =I12/$I$15 -> 0.14 | L12: Touring | M12: 1 | N12: 345000 | O12: 345000 | R12: Yamaha Aerox 155 | S12: 124000 | U12: air-cooled | V12: =COUNTIFS(CLEANED_MotorPH_Products_List_2!F:F,'Product Analysis'!U12) -> 13 | W12: =V12/SUM($V$11:$V$14) -> 0.26 | Y12: Touring | Z12: =COUNTIFS(CLEANED_MotorPH_Products_List_2!C:C,'Product Analysis'!Y12) -> 1 | AA12: =Z12/SUM($Z$4:$Z$20) -> 0.02
A13: Maximum | B13: 995000 | D13: Retro | E13: 1 | F13: 0.02 | H13: 2023 | I13: 17 | J13: =I13/$I$15 -> 0.34 | L13: Underbone | M13: 3 | N13: 318700 | O13: 106233.33 | R13: Honda Click 125i | S13: 80900 | U13: oil-cooled | V13: =COUNTIFS(CLEANED_MotorPH_Products_List_2!F:F,'Product Analysis'!U13) -> 2 | W13: =V13/SUM($V$11:$V$14) -> 0.04 | Y13: Underbone | Z13: =COUNTIFS(CLEANED_MotorPH_Products_List_2!C:C,'Product Analysis'!Y13) -> 3 | AA13: =Z13/SUM($Z$4:$Z$20) -> 0.06
A14: Sum | B14: 12893600 | D14: Sport touring | E14: 1 | F14: 0.02 | H14: 2024 | I14: 21 | J14: =I14/$I$15 -> 0.42 | L14: Scrambler | M14: 1 | N14: 295000 | O14: 295000 | R14: Suzuki Burgman Street 125 | S14: 80900 | U14: air | V14: =COUNTIFS(CLEANED_MotorPH_Products_List_2!F:F,'Product Analysis'!U14) -> 1 | W14: =V14/SUM($V$11:$V$14) -> 0.02 | Y14: Scrambler | Z14: =COUNTIFS(CLEANED_MotorPH_Products_List_2!C:C,'Product Analysis'!Y14) -> 1 | AA14: =Z14/SUM($Z$4:$Z$20) -> 0.02
A15: Count | B15: 50 | D15: Scrambler | E15: 1 | F15: 0.02 | H15: Grand Total | I15: 50 | L15: Classic | M15: 1 | N15: 250000 | O15: 250000 | R15: Suzuki Avenis 125 | S15: 79900 | Y15: Classic | Z15: =COUNTIFS(CLEANED_MotorPH_Products_List_2!C:C,'Product Analysis'!Y15) -> 1 | AA15: =Z15/SUM($Z$4:$Z$20) -> 0.02
D16: Standard | E16: 1 | F16: 0.02 | L16: Sport touring | M16: 1 | N16: 199900 | O16: 199900 | Q16: Cruiser | R16: Honda Rebel 1100 | S16: 650000 | U16: Displacement (cc) | V16: Count | W16: Count % | Y16: Sport touring | Z16: =COUNTIFS(CLEANED_MotorPH_Products_List_2!C:C,'Product Analysis'!Y16) -> 1 | AA16: =Z16/SUM($Z$4:$Z$20) -> 0.02
D17: Touring | E17: 1 | F17: 0.02 | L17: Retro | M17: 1 | N17: 182000 | O17: 182000 | R17: Harley-Davidson Street 750 | S17: 499000 | U17: 471cc | V17: =COUNTIFS(CLEANED_MotorPH_Products_List_2!G:G,'Product Analysis'!U17) -> 2 | W17: =V17/SUM($V$17:$V$46) -> 0.040816327 | Y17: Retro | Z17: =COUNTIFS(CLEANED_MotorPH_Products_List_2!C:C,'Product Analysis'!Y17) -> 1 | AA17: =Z17/SUM($Z$4:$Z$20) -> 0.02
D18: Street | E18: 1 | F18: 0.02 | L18: Commuter | M18: 2 | N18: 115900 | O18: 57950 | R18: Bristol Bobber 650 | S18: 398000 | U18: 155cc | V18: =COUNTIFS(CLEANED_MotorPH_Products_List_2!G:G,'Product Analysis'!U18) -> 5 | W18: =V18/SUM($V$17:$V$46) -> 0.10204082 | Y18: Commuter | Z18: =COUNTIFS(CLEANED_MotorPH_Products_List_2!C:C,'Product Analysis'!Y18) -> 2 | AA18: =Z18/SUM($Z$4:$Z$20) -> 0.04
L19: Street | M19: 1 | N19: 99900 | O19: 99900 | R19: Benelli 502C | S19: 349000 | U19: 399cc | V19: =COUNTIFS(CLEANED_MotorPH_Products_List_2!G:G,'Product Analysis'!U19) -> 2 | W19: =V19/SUM($V$17:$V$46) -> 0.040816327 | Y19: Street | Z19: =COUNTIFS(CLEANED_MotorPH_Products_List_2!C:C,'Product Analysis'!Y19) -> 1 | AA19: =Z19/SUM($Z$4:$Z$20) -> 0.02
L20: Standard | M20: 1 | N20: 68900 | O20: 68900 | Q20: Naked bike | R20: KTM 790 Duke | S20: 599000 | U20: 150cc | V20: =COUNTIFS(CLEANED_MotorPH_Products_List_2!G:G,'Product Analysis'!U20) -> 3 | W20: =V20/SUM($V$17:$V$46) -> 0.06122449 | Y20: Standard | Z20: =COUNTIFS(CLEANED_MotorPH_Products_List_2!C:C,'Product Analysis'!Y20) -> 1 | AA20: =Z20/SUM($Z$4:$Z$20) -> 0.02
L21: Grand Total | M21: 50 | N21: 12893600 | O21: 257872 | R21: Kawasaki Z400 | S21: 331000 | U21: 349cc | V21: =COUNTIFS(CLEANED_MotorPH_Products_List_2!G:G,'Product Analysis'!U21) -> 1 | W21: =V21/SUM($V$17:$V$46) -> 0.020408163
R22: Yamaha MT-15 | S22: 178000 | U22: 292cc | V22: =COUNTIFS(CLEANED_MotorPH_Products_List_2!G:G,'Product Analysis'!U22) -> 3 | W22: =V22/SUM($V$17:$V$46) -> 0.06122449
R23: KTM Duke 200 | S23: 178000 | U23: 199cc | V23: =COUNTIFS(CLEANED_MotorPH_Products_List_2!G:G,'Product Analysis'!U23) -> 2 | W23: =V23/SUM($V$17:$V$46) -> 0.040816327
R24: CFMoto 300NK | S24: 165000 | U24: 373cc | V24: =COUNTIFS(CLEANED_MotorPH_Products_List_2!G:G,'Product Analysis'!U24) -> 2 | W24: =V24/SUM($V$17:$V$46) -> 0.040816327
R25: TVS Apache RTR 200 4V | S25: 129000 | U25: 157cc | V25: =COUNTIFS(CLEANED_MotorPH_Products_List_2!G:G,'Product Analysis'!U25) -> 1 | W25: =V25/SUM($V$17:$V$46) -> 0.020408163
R26: Suzuki GSX-S150 | S26: 125000 | U26: 124cc | V26: =COUNTIFS(CLEANED_MotorPH_Products_List_2!G:G,'Product Analysis'!U26) -> 2 | W26: =V26/SUM($V$17:$V$46) -> 0.040816327
Q27: Heritage | R27: BMW R nineT | S27: 995000 | U27: 313cc | V27: =COUNTIFS(CLEANED_MotorPH_Products_List_2!G:G,'Product Analysis'!U27) -> 1 | W27: =V27/SUM($V$17:$V$46) -> 0.020408163
R28: Moto Guzzi V7 Stone | S28: 689000 | U28: 197cc | V28: =COUNTIFS(CLEANED_MotorPH_Products_List_2!G:G,'Product Analysis'!U28) -> 1 | W28: =V28/SUM($V$17:$V$46) -> 0.020408163
Q29: Sport | R29: Honda CBR500R | S29: 389000 | U29: 147cc | V29: =COUNTIFS(CLEANED_MotorPH_Products_List_2!G:G,'Product Analysis'!U29) -> 1 | W29: =V29/SUM($V$17:$V$46) -> 0.020408163
R30: Kawasaki Ninja 400 | S30: 340000 | U30: 649cc | V30: =COUNTIFS(CLEANED_MotorPH_Products_List_2!G:G,'Product Analysis'!U30) -> 3 | W30: =V30/SUM($V$17:$V$46) -> 0.06122449
R31: KTM RC 200 | S31: 198000 | U31: 149cc | V31: =COUNTIFS(CLEANED_MotorPH_Products_List_2!G:G,'Product Analysis'!U31) -> 3 | W31: =V31/SUM($V$17:$V$46) -> 0.06122449
R32: CFMoto 300SR | S32: 165000 | U32: 223cc | V32: =COUNTIFS(CLEANED_MotorPH_Products_List_2!G:G,'Product Analysis'!U32) -> 1 | W32: =V32/SUM($V$17:$V$46) -> 0.020408163
Q33: Adventure | R33: Moto Morini X-Cape 650 | S33: 369000 | U33: 125cc | V33: =COUNTIFS(CLEANED_MotorPH_Products_List_2!G:G,'Product Analysis'!U33) -> 3 | W33: =V33/SUM($V$17:$V$46) -> 0.06122449
R34: BMW G 310 GS | S34: 320000 | U34: 286cc | V34: =COUNTIFS(CLEANED_MotorPH_Products_List_2!G:G,'Product Analysis'!U34) -> 1 | W34: =V34/SUM($V$17:$V$46) -> 0.020408163
R35: Zontes 310X | S35: 248000 | U35: 749cc | V35: =COUNTIFS(CLEANED_MotorPH_Products_List_2!G:G,'Product Analysis'!U35) -> 1 | W35: =V35/SUM($V$17:$V$46) -> 0.020408163
R36: Motorstar Xplorer 250R | S36: 78900 | U36: 312cc | V36: =COUNTIFS(CLEANED_MotorPH_Products_List_2!G:G,'Product Analysis'!U36) -> 1 | W36: =V36/SUM($V$17:$V$46) -> 0.020408163
Q37: Dual-sport | R37: Yamaha Serow 250 | S37: 299000 | U37: 174cc | V37: =COUNTIFS(CLEANED_MotorPH_Products_List_2!G:G,'Product Analysis'!U37) -> 1 | W37: =V37/SUM($V$17:$V$46) -> 0.020408163
R38: Honda CRF300L | S38: 284900 | U38: 500cc | V38: =COUNTIFS(CLEANED_MotorPH_Products_List_2!G:G,'Product Analysis'!U38) -> 1 | W38: =V38/SUM($V$17:$V$46) -> 0.020408163
R39: Kawasaki KLX 230 | S39: 199000 | U39: 278cc | V39: =COUNTIFS(CLEANED_MotorPH_Products_List_2!G:G,'Product Analysis'!U39) -> 1 | W39: =V39/SUM($V$17:$V$46) -> 0.020408163
Q40: Cafe racer | R40: Bristol Veloce 500 | S40: 328000 | U40: 233cc | V40: =COUNTIFS(CLEANED_MotorPH_Products_List_2!G:G,'Product Analysis'!U40) -> 1 | W40: =V40/SUM($V$17:$V$46) -> 0.020408163
...

Sheet CLEANED_MotorPH_Products_List_2
A1: Product ID Number | B1: Product Name | C1: Product Type | D1: Unit Price (PHP) | E1: Engine Type | F1: Cooling System | G1: Displacement (cc) | H1: Transmission | I1: Manufacturing Date | J1: Date of Acquisition | K1: Segment
A2: 1 | B2: Honda CBR500R | C2: Sport | D2: 389000 | E2: Parallel-twin | F2: liquid-cooled | G2: 471cc | H2: 6-speed | I2: 2021 | J2: 2023 | K2: Mid-range
A3: 2 | B3: Yamaha MT-15 | C3: Naked bike | D3: 178000 | E3: Single cylinder | F3: liquid-cooled | G3: 155cc | H3: 6-speed | I3: 2022 | J3: 2023 | K3: Entry-level
A4: 3 | B4: Kawasaki Ninja 400 | C4: Sport | D4: 340000 | E4: Parallel-twin | F4: liquid-cooled | G4: 399cc | H4: 6-speed | I4: 2023 | J4: 2024 | K4: Mid-range
A5: 4 | B5: Suzuki Raider R150 Fi | C5: Underbone | D5: 119900 | E5: Single cylinder | F5: liquid-cooled | G5: 150cc | H5: 6-speed | I5: 2020 | J5: 2021 | K5: Entry-level
A6: 5 | B6: Royal Enfield Classic 350 | C6: Classic | D6: 250000 | E6: Single cylinder | F6: air-cooled | G6: 349cc | H6: 5-speed | I6: 2022 | J6: 2023 | K6: Mid-range
A7: 6 | B7: CFMoto 300NK | C7: Naked bike | D7: 165000 | E7: Single cylinder | F7: liquid-cooled | G7: 292cc | H7: 6-speed | I7: 2021 | J7: 2022 | K7: Mid-range
A8: 7 | B8: Bristol Veloce 500 | C8: Cafe racer | D8: 328000 | E8: Twin cylinder | F8: air-cooled | G8: 471cc | H8: 6-speed | I8: 2022 | J8: 2023 | K8: Mid-range
A9: 8 | B9: KTM Duke 200 | C9: Naked bike | D9: 178000 | E9: Single cylinder | F9: liquid-cooled | G9: 199cc | H9: 6-speed | I9: 2023 | J9: 2024 | K9: Entry-level
A10: 9 | B10: Yamaha XSR155 | C10: Retro | D10: 182000 | E10: Single cylinder | F10: liquid-cooled | G10: 155cc | H10: 6-speed | I10: 2022 | J10: 2023 | K10: Entry-level
A11: 10 | B11: Bajaj Dominar 400 | C11: Sport touring | D11: 199900 | E11: Single cylinder | F11: liquid-cooled | G11: 373cc | H11: 6-speed | I11: 2021 | J11: 2022 | K11: Mid-range
A12: 11 | B12: Yamaha NMAX 155 | C12: Scooter | D12: 151900 | E12: Single cylinder | F12: liquid-cooled | G12: 155cc | H12: CVT | I12: 2022 | J12: 2023 | K12: Entry-level
A13: 12 | B13: Honda ADV 160 | C13: Scooter | D13: 164900 | E13: Single cylinder | F13: liquid-cooled | G13: 157cc | H13: CVT | I13: 2023 | J13: 2024 | K13: Entry-level
... A41: 40 | B41: Kawasaki KLX 230 | C41: Dual-sport | D41: 199000 | E41: Single cylinder | F41: air-cooled | G41: 233cc | H41: 6-speed | I41: 2022 | J41: 2023 | K41: Mid-range
A42: 41 | B42: BMW R nineT | C42: Heritage | D42: 995000 | E42: Flat twin | F42: air | I42: 2023 | J42: 2024 | K42: Premium
A43: 42 | B43: Honda Rebel 1100 | C43: Cruiser | D43: 650000 | E43: Parallel-twin | F43: liquid-cooled | G43: 1084cc | H43: 6-speed | I43: 2023 | J43: 2024 | K43: Premium
A44: 43 | B44: KTM 790 Duke | C44: Naked bike | D44: 599000 | E44: Parallel-twin | F44: liquid-cooled | G44: 799cc | H44: 6-speed | I44: 2023 | J44: 2024 | K44: Premium
A45: 44 | B45: CFMoto 300SR | C45: Sport | D45: 165000 | E45: Single cylinder | F45: liquid-cooled | G45: 292cc | H45: 6-speed | I45: 2023 | J45: 2024 | K45: Mid-range
A46: 45 | B46: Italjet Dragster 200 | C46: Scooter | D46: 289000 | E46: Single cylinder | F46: liquid-cooled | G46: 181cc | H46: CVT | I46: 2023 | J46: 2024 | K46: Entry-level
A47: 46 | B47: Yamaha Serow 250 | C47: Dual-sport | D47: 299000 | E47: Single cylinder | F47: air-cooled | G47: 249cc | H47: 5-speed | I47: 2020 | J47: 2021 | K47: Mid-range
A48: 47 | B48: Suzuki Burgman Street 125 | C48: Scooter | D48: 80900 | E48: Single cylinder | F48: air-cooled | G48: 124cc | H48: CVT | I48: 2023 | J48: 2024 | K48: Entry-level
A49: 48 | B49: Zontes GK350 | C49: Cafe racer | D49: 269000 | E49: Single cylinder | F49: liquid-cooled | G49: 348cc | H49: 6-speed | I49: 2023 | J49: 2024 | K49: Mid-range
A50: 49 | B50: Moto Guzzi V7 Stone | C50: Heritage | D50: 689000 | E50: V-twin | F50: air-cooled | G50: 853cc | H50: 6-speed | I50: 2022 | J50: 2023 | K50: Premium
A51: 50 | B51: SYM Husky 150 | C51: Underbone | D51: 72900 | E51: Single cylinder | F51: air-cooled | G51: 150cc | H51: CVT | I51: 2022 | J51: 2023 | K51: Entry-level

Sheet MotorPH_Sales Data-3rd Quarter-
A1: Date | B1: Month | C1: Day | D1: Year | E1: Client_Type | F1: Product | G1: UnitPrice | H1: Quantity | I1: Total | J1: Payment | K1: Product Type | L1: Engine Type | M1: Cooling System | N1: Displacement (cc) | O1: Segment | P1: Mark up Rate | Q1: Transmission
A2: 45860 | B2: =TEXT(MotorPHSales[[#This Row],[Date]],"mmmm") -> July | C2: =DAY(MotorPHSales[[#This Row],[Date]]) -> 22 | D2: =YEAR(MotorPHSales[[#This Row],[Date]]) -> 2025 | E2: Retail | F2: Zontes GK350 | G2: 269000 | H2: 20 | I2: 5380000 | J2: Cash | K2: =INDEX(CLEANED_MotorPH_Products_List_2!C:C,MATCH(MotorPHSales[[#This Row],[Product]],CLEANED_MotorPH_Products_List_2!$B:$B,0)) -> Cafe racer | L2: =INDEX(CLEANED_MotorPH_Products_List_2!E:E,MATCH(MotorPHSales[[#This Row],[Product]],CLEANED_MotorPH_Products_List_2!$B:$B,0)) -> Single cylinder | M2: =INDEX(CLEANED_MotorPH_Products_List_2!F:F,MATCH(MotorPHSales[[#This Row],[Product]],CLEANED_MotorPH_Products_List_2!$B:$B,0)) -> liquid-cooled | N2: =INDEX(CLEANED_MotorPH_Products_List_2!G:G,MATCH(MotorPHSales[[#This Row],[Product]],CLEANED_MotorPH_Products_List_2!$B:$B,0)) -> 348cc | O2: =INDEX(CLEANED_MotorPH_Products_List_2!K:K,MATCH(MotorPHSales[[#This Row],[Product]],CLEANED_MotorPH_Products_List_2!B:B,0)) -> Mid-range | P2: =IF(MotorPHSales[[#This Row],[Segment]]="Entry-level",MotorPHSales[[#This Row],[UnitPrice]]/(1+30%),IF(MotorPHSales[[#This Row],[Segment]]="Mid-range",MotorPHSales[[#This Row],[UnitPrice]]/(1+35%),MotorPHSales[[#This Row],[UnitPrice]]/(1+40%)))*MotorPHSales[[#This Row],[Quantity]] -> 3985185.2 | Q2: =INDEX(CLEANED_MotorPH_Products_List_2!H:H,MATCH(MotorPHSales[[#This Row],[Product]],CLEANED_MotorPH_Products_List_2!$B:$B,0)) -> 6-speed
A3: 45823 | B3: =TEXT(MotorPHSales[[#This Row],[Date]],"mmmm") -> June | C3: =DAY(MotorPHSales[[#This Row],[Date]]) -> 15 | D3: =YEAR(MotorPHSales[[#This Row],[Date]]) -> 2025 | E3: Wholesale | F3: Yamaha FZi 150 | G3: 99900 | H3: 18 | I3: 1798200 | J3: Credit card | K3: =INDEX(CLEANED_MotorPH_Products_List_2!C:C,MATCH(MotorPHSales[[#This Row],[Product]],CLEANED_MotorPH_Products_List_2!$B:$B,0)) -> Street | L3: =INDEX(CLEANED_MotorPH_Products_List_2!E:E,MATCH(MotorPHSales[[#This Row],[Product]],CLEANED_MotorPH_Products_List_2!$B:$B,0)) -> Single cylinder | M3: =INDEX(CLEANED_MotorPH_Products_List_2!F:F,MATCH(MotorPHSales[[#This Row],[Product]],CLEANED_MotorPH_Products_List_2!$B:$B,0)) -> air-cooled | N3: =INDEX(CLEANED_MotorPH_Products_List_2!G:G,MATCH(MotorPHSales[[#This Row],[Product]],CLEANED_MotorPH_Products_List_2!$B:$B,0)) -> 149cc | O3: =INDEX(CLEANED_MotorPH_Products_List_2!K:K,MATCH(MotorPHSales[[#This Row],[Product]],CLEANED_MotorPH_Products_List_2!B:B,0)) -> Entry-level | P3: =IF(MotorPHSales[[#This Row],[Segment]]="Entry-level",MotorPHSales[[#This Row],[UnitPrice]]/(1+30%),IF(MotorPHSales[[#This Row],[Segment]]="Mid-range",MotorPHSales[[#This Row],[UnitPrice]]/(1+35%),MotorPHSales[[#This Row],[UnitPrice]]/(1+40%)))*MotorPHSales[[#This Row],[Quantity]] -> 1383230.8 | Q3: =INDEX(CLEANED_MotorPH_Products_List_2!H:H,MATCH(MotorPHSales[[#This Row],[Product]],CLEANED_MotorPH_Products_List_2!$B:$B,0)) -> 5-speed
A4: 45880 | B4: =TEXT(MotorPHSales[[#This Row],[Date]],"mmmm") -> August | C4: =DAY(MotorPHSales[[#This Row],[Date]]) -> 11 | D4: =YEAR(MotorPHSales[[#This Row],[Date]]) -> 2025 | E4: Wholesale | F4: Zontes GK350 | G4: 269000 | H4: 41 | I4: 11029000 | J4: Credit card | K4: =INDEX(CLEANED_MotorPH_Products_List_2!C:C,MATCH(MotorPHSales[[#This Row],[Product]],CLEANED_MotorPH_Products_List_2!$B:$B,0)) -> Cafe racer | L4: =INDEX(CLEANED_MotorPH_Products_List_2!E:E,MATCH(MotorPHSales[[#This Row],[Product]],CLEANED_MotorPH_Products_List_2!$B:$B,0)) -> Single cylinder | M4: =INDEX(CLEANED_MotorPH_Products_List_2!F:F,MATCH(MotorPHSales[[#This Row],[Product]],CLEANED_MotorPH_Products_List_2!$B:$B,0)) -> liquid-cooled | N4: =INDEX(CLEANED_MotorPH_Products_List_2!G:G,MATCH(MotorPHSales[[#This Row],[Product]],CLEANED_MotorPH_Products_List_2!$B:$B,0)) -> 348cc | O4: =INDEX(CLEANED_MotorPH_Products_List_2!K:K,MATCH(MotorPHSales[[#This Row],[Product]],CLEANED_MotorPH_Products_List_2!B:B,0)) -> Mid-range | P4: =IF(MotorPHSales[[#This Row],[Segment]]="Entry-level",MotorPHSales[[#This Row],[UnitPrice]]/(1+30%),IF(MotorPHSales[[#This Row],[Segment]]="Mid-range",MotorPHSales[[#This Row],[UnitPrice]]/(1+35%),MotorPHSales[[#This Row],[UnitPrice]]/(1+40%)))*MotorPHSales[[#This Row],[Quantity]] -> 8169629.6 | Q4: =INDEX(CLEANED_MotorPH_Products_List_2!H:H,MATCH(MotorPHSales[[#This Row],[Product]],CLEANED_MotorPH_Products_List_2!$B:$B,0)) -> 6-speed
A5: 45869 | B5: =TEXT(MotorPHSales[[#This Row],[Date]],"mmmm") -> July | C5: =DAY(MotorPHSales[[#This Row],[Date]]) -> 31 | D5: =YEAR(MotorPHSales[[#This Row],[Date]]) -> 2025 | E5: Retail | F5: Italjet Dragster 200 | G5: 867000 | H5: 50 | I5: 14450000 | J5: Cash | K5: =INDEX(CLEANED_MotorPH_Products_List_2!C:C,MATCH(MotorPHSales[[#This Row],[Product]],CLEANED_MotorPH_Products_List_2!$B:$B,0)) -> Scooter | L5: =INDEX(CLEANED_MotorPH_Products_List_2!E:E,MATCH(MotorPHSales[[#This Row],[Product]],CLEANED_MotorPH_Products_List_2!$B:$B,0)) -> Single cylinder | M5: =INDEX(CLEANED_MotorPH_Products_List_2!F:F,MATCH(MotorPHSales[[#This Row],[Product]],CLEANED_MotorPH_Products_List_2!$B:$B,0)) -> liquid-cooled | N5: =INDEX(CLEANED_MotorPH_Products_List_2!G:G,MATCH(MotorPHSales[[#This Row],[Product]],CLEANED_MotorPH_Products_List_2!$B:$B,0)) -> 181cc | O5: =INDEX(CLEANED_MotorPH_Products_List_2!K:K,MATCH(MotorPHSales[[#This Row],[Product]],CLEANED_MotorPH_Products_List_2!B:B,0)) -> Entry-level | P5: =IF(MotorPHSales[[#This Row],[Segment]]="Entry-level",MotorPHSales[[#This Row],[UnitPrice]]/(1+30%),IF(MotorPHSales[[#This Row],[Segment]]="Mid-range",MotorPHSales[[#This Row],[UnitPrice]]/(1+35%),MotorPHSales[[#This Row],[UnitPrice]]/(1+40%)))*MotorPHSales[[#This Row],[Quantity]] -> 33346154 | Q5: =INDEX(CLEANED_MotorPH_Products_List_2!H:H,MATCH(MotorPHSales[[#This Row],[Product]],CLEANED_MotorPH_Products_List_2!$B:$B,0)) -> CVT
A6: 45829 | B6: =TEXT(MotorPHSales[[#This Row],[Date]],"mmmm") -> June | C6: =DAY(MotorPHSales[[#This Row],[Date]]) -> 21 | D6: =YEAR(MotorPHSales[[#This Row],[Date]]) -> 2025 | E6: Wholesale | F6: Zontes 310X | G6: 248000 | H6: 7 | I6: 1736000 | J6: Cash | K6: =INDEX(CLEANED_MotorPH_Products_List_2!C:C,MATCH(MotorPHSales[[#This Row],[Product]],CLEANED_MotorPH_Products_List_2!$B:$B,0)) -> Adventure | L6: =INDEX(CLEANED_MotorPH_Products_List_2!E:E,MATCH(MotorPHSales[[#This Row],[Product]],CLEANED_MotorPH_Products_List_2!$B:$B,0)) -> Single cylinder | M6: =INDEX(CLEANED_MotorPH_Products_List_2!F:F,MATCH(MotorPHSales[[#This Row],[Product]],CLEANED_MotorPH_Products_List_2!$B:$B,0)) -> liquid-cooled | N6: =INDEX(CLEANED_MotorPH_Products_List_2!G:G,MATCH(MotorPHSales[[#This Row],[Product]],CLEANED_MotorPH_Products_List_2!$B:$B,0)) -> 312cc | O6: =INDEX(CLEANED_MotorPH_Products_List_2!K:K,MATCH(MotorPHSales[[#This Row],[Product]],CLEANED_MotorPH_Products_List_2!B:B,0)) -> Mid-range | P6: =IF(MotorPHSales[[#This Row],[Segment]]="Entry-level",MotorPHSales[[#This Row],[UnitPrice]]/(1+30%),IF(MotorPHSales[[#This Row],[Segment]]="Mid-range",MotorPHSales[[#This Row],[UnitPrice]]/(1+35%),MotorPHSales[[#This Row],[UnitPrice]]/(1+40%)))*MotorPHSales[[#This Row],[Quantity]] -> 1285925.9 | Q6: =INDEX(CLEANED_MotorPH_Products_List_2!H:H,MATCH(MotorPHSales[[#This Row],[Product]],CLEANED_MotorPH_Products_List_2!$B:$B,0)) -> 6-speed
A7: 45891 | B7: =TEXT(MotorPHSales[[#This Row],[Date]],"mmmm") -> August | C7: =DAY(MotorPHSales[[#This Row],[Date]]) -> 22 | D7: =YEAR(MotorPHSales[[#This Row],[Date]]) -> 2025 | E7: Retail | F7: Zontes 310X | G7: 248000 | H7: 3 | I7: 744000 | J7: Cash | K7: =INDEX(CLEANED_MotorPH_Products_List_2!C:C,MATCH(MotorPHSales[[#This Row],[Product]],CLEANED_MotorPH_Products_List_2!$B:$B,0)) -> Adventure | L7: =INDEX(CLEANED_MotorPH_Products_List_2!E:E,MATCH(MotorPHSales[[#This Row],[Product]],CLEANED_MotorPH_Products_List_2!$B:$B,0)) -> Single cylinder | M7: =INDEX(CLEANED_MotorPH_Products_List_2!F:F,MATCH(MotorPHSales[[#This Row],[Product]],CLEANED_MotorPH_Products_List_2!$B:$B,0)) -> liquid-cooled | N7: =INDEX(CLEANED_MotorPH_Products_List_2!G:G,MATCH(MotorPHSales[[#This Row],[Product]],CLEANED_MotorPH_Products_List_2!$B:$B,0)) -> 312cc | O7: =INDEX(CLEANED_MotorPH_Products_List_2!K:K,MATCH(MotorPHSales[[#This Row],[Product]],CLEANED_MotorPH_Products_List_2!B:B,0)) -> Mid-range | P7: =IF(MotorPHSales[[#This Row],[Segment]]="Entry-level",MotorPHSales[[#This Row],[UnitPrice]]/(1+30%),IF(MotorPHSales[[#This Row],[Segment]]="Mid-range",MotorPHSales[[#This Row],[UnitPrice]]/(1+35%),MotorPHSales[[#This Row],[UnitPrice]]/(1+40%)))*MotorPHSales[[#This Row],[Quantity]] -> 551111.11 | Q7: =INDEX(CLEANED_MotorPH_Products_List_2!H:H,MATCH(MotorPHSales[[#This Row],[Product]],CLEANED_MotorPH_Products_List_2!$B:$B,0)) -> 6-speed
A8: 45895 | B8: =TEXT(MotorPHSales[[#This Row],[Date]],"mmmm") -> August | C8: =DAY(MotorPHSales[[#This Row],[Date]]) -> 26 | D8: =YEAR(MotorPHSales[[#This Row],[Date]]) -> 2025 | E8: Retail | F8: Yamaha Aerox 155 | G8: 124000 | H8: 28 | I8: 3472000 | J8: Credit card | K8: =INDEX(CLEANED_MotorPH_Products_List_2!C:C,MATCH(MotorPHSales[[#This Row],[Product]],CLEANED_MotorPH_Products_List_2!$B:$B,0)) -> Scooter | L8: =INDEX(CLEANED_MotorPH_Products_List_2!E:E,MATCH(MotorPHSales[[#This Row],[Product]],CLEANED_MotorPH_Products_List_2!$B:$B,0)) -> Single cylinder | M8: =INDEX(CLEANED_MotorPH_Products_List_2!F:F,MATCH(MotorPHSales[[#This Row],[Product]],CLEANED_MotorPH_Products_List_2!$B:$B,0)) -> liquid-cooled | N8: =INDEX(CLEANED_MotorPH_Products_List_2!G:G,MATCH(MotorPHSales[[#This Row],[Product]],CLEANED_MotorPH_Products_List_2!$B:$B,0)) -> 155cc | O8: =INDEX(CLEANED_MotorPH_Products_List_2!K:K,MATCH(MotorPHSales[[#This Row],[Product]],CLEANED_MotorPH_Products_List_2!B:B,0)) -> Entry-level | P8: =IF(MotorPHSales[[#This Row],[Segment]]="Entry-level",MotorPHSales[[#This Row],[UnitPrice]]/(1+30%),IF(MotorPHSales[[#This Row],[Segment]]="Mid-range",MotorPHSales[[#This Row],[UnitPrice]]/(1+35%),MotorPHSales[[#This Row],[UnitPrice]]/(1+40%)))*MotorPHSales[[#This Row],[Quantity]] -> 2670769.2 | Q8: =INDEX(CLEANED_MotorPH_Products_List_2!H:H,MATCH(MotorPHSales[[#This Row],[Product]],CLEANED_MotorPH_Products_List_2!$B:$B,0)) -> CVT
A9: 45883 | B9: =TEXT(MotorPHSales[[#This Row],[Date]],"mmmm") -> August | C9: =DAY(MotorPHSales[[#This Row],[Date]]) -> 14 | D9: =YEAR(MotorPHSales[[#This Row],[Date]]) -> 2025 | E9: Retail | F9: Bajaj Dominar 400 | G9: 199900 | H9: 12 | I9: 2398800 | J9: Transfer | K9: =INDEX(CLEANED_MotorPH_Products_List_2!C:C,MATCH(MotorPHSales[[#This Row],[Product]],CLEANED_MotorPH_Products_List_2!$B:$B,0)) -> Sport touring | L9: =INDEX(CLEANED_MotorPH_Products_List_2!E:E,MATCH(MotorPHSales[[#This Row],[Product]],CLEANED_MotorPH_Products_List_2!$B:$B,0)) -> Single cylinder | M9: =INDEX(CLEANED_MotorPH_Products_List_2!F:F,MATCH(MotorPHSales[[#This Row],[Product]],CLEANED_MotorPH_Products_List_2!$B:$B,0)) -> liquid-cooled | N9: =INDEX(CLEANED_MotorPH_Products_List_2!G:G,MATCH(MotorPHSales[[#This Row],[Product]],CLEANED_MotorPH_Products_List_2!$B:$B,0)) -> 373cc | O9: =INDEX(CLEANED_MotorPH_Products_List_2!K:K,MATCH(MotorPHSales[[#This Row],[Product]],CLEANED_MotorPH_Products_List_2!B:B,0)) -> Mid-range | P9: =IF(MotorPHSales[[#This Row],[Segment]]="Entry-level",MotorPHSales[[#This Row],[UnitPrice]]/(1+30%),IF(MotorPHSales[[#This Row],[Segment]]="Mid-range",MotorPHSales[[#This Row],[UnitPrice]]/(1+35%),MotorPHSales[[#This Row],[UnitPrice]]/(1+40%)))*MotorPHSales[[#This Row],[Quantity]] -> 1776888.9 | Q9: =INDEX(CLEANED_MotorPH_Products_List_2!H:H,MATCH(MotorPHSales[[#This Row],[Product]],CLEANED_MotorPH_Products_List_2!$B:$B,0)) -> 6-speed
A10: 45896 | B10: =TEXT(MotorPHSales[[#This Row],[Date]],"mmmm") -> August | C10: =DAY(MotorPHSales[[#This Row],[Date]]) -> 27 | D10: =YEAR(MotorPHSales[[#This Row],[Date]]) -> 2025 | E10: Wholesale | F10: KTM 790 Duke | G10: 599000 | H10: 46 | I10: 27554000 | J10: Credit card | K10: =INDEX(CLEANED_MotorPH_Products_List_2!C:C,MATCH(MotorPHSales[[#This Row],[Product]],CLEANED_MotorPH_Products_List_2!$B:$B,0)) -> Naked bike | L10: =INDEX(CLEANED_MotorPH_Products_List_2!E:E,MATCH(MotorPHSales[[#This Row],[Product]],CLEANED_MotorPH_Products_List_2!$B:$B,0)) -> Parallel-twin | M10: =INDEX(CLEANED_MotorPH_Products_List_2!F:F,MATCH(MotorPHSales[[#This Row],[Product]],CLEANED_MotorPH_Products_List_2!$B:$B,0)) -> liquid-cooled | N10: =INDEX(CLEANED_MotorPH_Products_List_2!G:G,MATCH(MotorPHSales[[#This Row],[Product]],CLEANED_MotorPH_Products_List_2!$B:$B,0)) -> 799cc | O10: =INDEX(CLEANED_MotorPH_Products_List_2!K:K,MATCH(MotorPHSales[[#This Row],[Product]],CLEANED_MotorPH_Products_List_2!B:B,0)) -> Premium | P10: =IF(MotorPHSales[[#This Row],[Segment]]="Entry-level",MotorPHSales[[#This Row],[UnitPrice]]/(1+30%),IF(MotorPHSales[[#This Row],[Segment]]="Mid-range",MotorPHSales[[#This Row],[UnitPrice]]/(1+35%),MotorPHSales[[#This Row],[UnitPrice]]/(1+40%)))*MotorPHSales[[#This Row],[Quantity]] -> 19681429 | Q10: =INDEX(CLEANED_MotorPH_Products_List_2!H:H,MATCH(MotorPHSales[[#This Row],[Product]],CLEANED_MotorPH_Products_List_2!$B:$B,0)) -> 6-speed
A11: 45832 | B11: =TEXT(MotorPHSales[[#This Row],[Date]],"mmmm") -> June | C11: =DAY(MotorPHSales[[#This Row],[Date]]) -> 24 | D11: =YEAR(MotorPHSales[[#This Row],[Date]]) -> 2025 | E11: Wholesale | F11: Vespa GTS Super 300 | G11: 398000 | H11: 19 | I11: 7562000 | J11: Credit card | K11: =INDEX(CLEANED_MotorPH_Products_List_2!C:C,MATCH(MotorPHSales[[#This Row],[Product]],CLEANED_MotorPH_Products_List_2!$B:$B,0)) -> Scooter | L11: =INDEX(CLEANED_MotorPH_Products_List_2!E:E,MATCH(MotorPHSales[[#This Row],[Product]],CLEANED_MotorPH_Products_List_2!$B:$B,0)) -> Single cylinder | M11: =INDEX(CLEANED_MotorPH_Products_List_2!F:F,MATCH(MotorPHSales[[#This Row],[Product]],CLEANED_MotorPH_Products_List_2!$B:$B,0)) -> liquid-cooled | N11: =INDEX(CLEANED_MotorPH_Products_List_2!G:G,MATCH(MotorPHSales[[#This Row],[Product]],CLEANED_MotorPH_Products_List_2!$B:$B,0)) -> 278cc | O11: =INDEX(CLEANED_MotorPH_Products_List_2!K:K,MATCH(MotorPHSales[[#This Row],[Product]],CLEANED_MotorPH_Products_List_2!B:B,0)) -> Mid-range | P11: =IF(MotorPHSales[[#This Row],[Segment]]="Entry-level",MotorPHSales[[#This Row],[UnitPrice]]/(1+30%),IF(MotorPHSales[[#This Row],[Segment]]="Mid-range",MotorPHSales[[#This Row],[UnitPrice]]/(1+35%),MotorPHSales[[#This Row],[UnitPrice]]/(1+40%)))*MotorPHSales[[#This Row],[Quantity]] -> 5601481.5 | Q11: =INDEX(CLEANED_MotorPH_Products_List_2!H:H,MATCH(MotorPHSales[[#This Row],[Product]],CLEANED_MotorPH_Products_List_2!$B:$B,0)) -> CVT
A12: 45811 | B12: =TEXT(MotorPHSales[[#This Row],[Date]],"mmmm") -> June | C12: =DAY(MotorPHSales[[#This Row],[Date]]) -> 3 | D12: =YEAR(MotorPHSales[[#This Row],[Date]]) -> 2025 | E12: Wholesale | F12: Moto Guzzi V7 Stone | G12: 689000 | H12: 13 | I12: 8957000 | J12: Cash | K12: =INDEX(CLEANED_MotorPH_Products_List_2!C:C,MATCH(MotorPHSales[[#This Row],[Product]],CLEANED_MotorPH_Products_List_2!$B:$B,0)) -> Heritage | L12: =INDEX(CLEANED_MotorPH_Products_List_2!E:E,MATCH(MotorPHSales[[#This Row],[Product]],CLEANED_MotorPH_Products_List_2!$B:$B,0)) -> V-twin | M12: =INDEX(CLEANED_MotorPH_Products_List_2!F:F,MATCH(MotorPHSales[[#This Row],[Product]],CLEANED_MotorPH_Products_List_2!$B:$B,0)) -> air-cooled | N12: =INDEX(CLEANED_MotorPH_Products_List_2!G:G,MATCH(MotorPHSales[[#This Row],[Product]],CLEANED_MotorPH_Products_List_2!$B:$B,0)) -> 853cc | O12: =INDEX(CLEANED_MotorPH_Products_List_2!K:K,MATCH(MotorPHSales[[#This Row],[Product]],CLEANED_MotorPH_Products_List_2!B:B,0)) -> Premium | P12: =IF(MotorPHSales[[#This Row],[Segment]]="Entry-level",MotorPHSales[[#This Row],[UnitPrice]]/(1+30%),IF(MotorPHSales[[#This Row],[Segment]]="Mid-range",MotorPHSales[[#This Row],[UnitPrice]]/(1+35%),MotorPHSales[[#This Row],[UnitPrice]]/(1+40%)))*MotorPHSales[[#This Row],[Quantity]] -> 6397857.1 | Q12: =INDEX(CLEANED_MotorPH_Products_List_2!H:H,MATCH(MotorPHSales[[#This Row],[Product]],CLEANED_MotorPH_Products_List_2!$B:$B,0)) -> 6-speed
A13: 45830 | B13: =TEXT(MotorPHSales[[#This Row],[Date]],"mmmm") -> June | C13: =DAY(MotorPHSales[[#This Row],[Date]]) -> 22 | D13: =YEAR(MotorPHSales[[#This Row],[Date]]) -> 2025 | E13: Retail | F13: Bristol Veloce 500 | G13: 328000 | H13: 4 | I13: 1312000 | J13: Credit card | K13: =INDEX(CLEANED_MotorPH_Products_List_2!C:C,MATCH(MotorPHSales[[#This Row],[Product]],CLEANED_MotorPH_Products_List_2!$B:$B,0)) -> Cafe racer | L13: =INDEX(CLEANED_MotorPH_Products_List_2!E:E,MATCH(MotorPHSales[[#This Row],[Product]],CLEANED_MotorPH_Products_List_2!$B:$B,0)) -> Twin cylinder | M13: =INDEX(CLEANED_MotorPH_Products_List_2!F:F,MATCH(MotorPHSales[[#This Row],[Product]],CLEANED_MotorPH_Products_List_2!$B:$B,0)) -> air-cooled | N13: =INDEX(CLEANED_MotorPH_Products_List_2!G:G,MATCH(MotorPHSales[[#This Row],[Product]],CLEANED_MotorPH_Products_List_2!$B:$B,0)) -> 471cc | O13: =INDEX(CLEANED_MotorPH_Products_List_2!K:K,MATCH(MotorPHSales[[#This Row],[Product]],CLEANED_MotorPH_Products_List_2!B:B,0)) -> Mid-range | P13: =IF(MotorPHSales[[#This Row],[Segment]]="Entry-level",MotorPHSales[[#This Row],[UnitPrice]]/(1+30%),IF(MotorPHSales[[#This Row],[Segment]]="Mid-range",MotorPHSales[[#This Row],[UnitPrice]]/(1+35%),MotorPHSales[[#This Row],[UnitPrice]]/(1+40%)))*MotorPHSales[[#This Row],[Quantity]] -> 971851.85 | Q13: =INDEX(CLEANED_MotorPH_Products_List_2!H:H,MATCH(MotorPHSales[[#This Row],[Product]],CLEANED_MotorPH_Products_List_2!$B:$B,0)) -> 6-speed
... A991: 45881 | B991: =TEXT(MotorPHSales[[#This Row],[Date]],"mmmm") -> August | C991: =DAY(MotorPHSales[[#This Row],[Date]]) -> 12 | D991: =YEAR(MotorPHSales[[#This Row],[Date]]) -> 2025 | E991: Retail | F991: SYM Jet X 150 | G991: 128000 | H991: 1 | I991: 128000 | J991: Credit card | K991: =INDEX(CLEANED_MotorPH_Products_List_2!C:C,MATCH(MotorPHSales[[#This Row],[Product]],CLEANED_MotorPH_Products_List_2!$B:$B,0)) -> Scooter | L991: =INDEX(CLEANED_MotorPH_Products_List_2!E:E,MATCH(MotorPHSales[[#This Row],[Product]],CLEANED_MotorPH_Products_List_2!$B:$B,0)) -> Single cylinder | M991: =INDEX(CLEANED_MotorPH_Products_List_2!F:F,MATCH(MotorPHSales[[#This Row],[Product]],CLEANED_MotorPH_Products_List_2!$B:$B,0)) -> liquid-cooled | N991: =INDEX(CLEANED_MotorPH_Products_List_2!G:G,MATCH(MotorPHSales[[#This Row],[Product]],CLEANED_MotorPH_Products_List_2!$B:$B,0)) -> 149cc | O991: =INDEX(CLEANED_MotorPH_Products_List_2!K:K,MATCH(MotorPHSales[[#This Row],[Product]],CLEANED_MotorPH_Products_List_2!B:B,0)) -> Entry-level | P991: =IF(MotorPHSales[[#This Row],[Segment]]="Entry-level",MotorPHSales[[#This Row],[UnitPrice]]/(1+30%),IF(MotorPHSales[[#This Row],[Segment]]="Mid-range",MotorPHSales[[#This Row],[UnitPrice]]/(1+35%),MotorPHSales[[#This Row],[UnitPrice]]/(1+40%)))*MotorPHSales[[#This Row],[Quantity]] -> 98461.538 | Q991: =INDEX(CLEANED_MotorPH_Products_List_2!H:H,MATCH(MotorPHSales[[#This Row],[Product]],CLEANED_MotorPH_Products_List_2!$B:$B,0)) -> CVT
